Workbook

Sheet werkzaamheden
A1: werk_code | B1: werk_omschrijving
A2: 1a | B2: Schonen wateren en maaien oevers - Schieland en Krimpen ad IJssel
A3: 1b | B3: Schonen van wateren - Krimpenerwaard
A4: 1c | B4: Uitkrabben natuurvriendelijke oevers
A5: 2a | B5: Maaien van primaire waterkeringen
A6: 2b | B6: Maaien van regionale waterkeringen
A7: 2c | B7: Maaien van wegbermen en oevers tot aan de waterlijn
A8: 2d | B8: Maaien eigen terreinen en rond kunstwerken
A9: 3 | B9: Baggeren van wateren (onderhoud)
A10: 4 | B10: Snoeien en dunnen van opgaande beplanting
A11: 5 | B11: Onderhoud aan waterkeringen, duikers, kaden en kunstwerken

Sheet gebieden
A1: gebied_code | B1: gebied_omschrijving | C1: subgebied_code | D1: subgebied_omschrijving
A2: SN | B2: Schieland noord | C2: EP | D2: Eendragtspolder
A3: SN | B3: Schieland noord | C3: GZ | D3: Glastuinbouwgebied Zuidplas (Moerkapelle)
A4: SN | B4: Schieland noord | C4: GL | D4: Glastuinbouwgebied Lansingerland (Bleiswijk)
A5: SN | B5: Schieland noord | C5: ZP | D5: Zuidplaspolder
A6: SZ | B6: Schieland zuid incl. Krimpen a/d Ijssel | C6: KV | D6: AWZI Kralingse Veer
A7: SZ | B7: Schieland zuid incl. Krimpen a/d Ijssel | C7: IJN | D7: IJsseldijk-Noord
A8: SZ | B8: Schieland zuid incl. Krimpen a/d Ijssel | C8: BK | D8: Bleiswijk Klappolder-zuid
A9: KW | B9: Krimpenerwaard west | C9: OU | D9: Ouderkerk a/d IJssel Tiendweg-oost
A10: KW | B10: Krimpenerwaard west | C10: NT | D10: Nessetiendweg
A11: KW | B11: Krimpenerwaard west | C11: BL | D11: Berkenwoudsche lage boezem
A12: KW | B12: Krimpenerwaard west | C12: BH | D12: Berkenwoudsche hoge boezem
... A18: KO | B18: Krimpenerwaard oost | C18: FK | D18: Fransekade

Sheet maatregelen
A1: maatregel_code | B1: maatregel_omschrijving | C1: maatregel_type | D1: fase | E1: Habitatbenadering. In deze kolom invullen: JA of NEE of als het niet uitmaakt laat je hem leeg
A2: S1 | B2: Maaien voor mei en/of vanaf september vanwege de zaadzetting. | C2: Maaien | D2: uitvoering
A3: S2 | B3: Groeiplaatsen van beschermde plantensoorten worden ontzien bij rijbewegingen en bij tijdelijke opslag van materieel. | C3: Maaien | D3: uitvoering
A4: S3 | B4: Schakel een ecologisch deskundige in op het gebied van planten om groeiplaatsen te markeren en een werkinstructie voor het maaien te ontvangen. | C4: Maaien | D4: voorbereiding
A5: S4 | B5: Het maaibeheer is vastgelegd in een beheerplan. | C5: Maaien | D5: voorbereiding
A6: A1 | B6: Voorkom insporing en beschadiging van bermen, oevers en beplanting (max. insporing 5 cm). | C6: Materieel en methode | D6: uitvoering
A7: A2 | B7: Rijd of vaar stapvoets (< 5 km/u). | C7: Materieel en methode | D7: uitvoering
A8: A3 | B8: Let altijd op alarmerende vogels en hun nesten. Nest gevonden? Stop en pas het werk aan. Houd 10 meter afstand tot het nest; Meld en registreer het nest. | C8: Soort- en habitatbescherming | D8: uitvoering
A9: A4 | B9: Werk richting een rustig gebied waar dieren kunnen ontsnappen | C9: Materieel en methode | D9: uitvoering
A10: A5 | B10: Maai minimaal 10 cm boven bodem of waterbodem | C10: Materieel en methode | D10: uitvoering
A11: A6 | B11: Gebruik waar mogelijk lage bandenspanning of andere bodemsparende technieken. Pas dit altijd toe op natte of kwetsbare plekken. | C11: Materieel en methode | D11: uitvoering
A12: A7 | B12: Werk overdag. Moet je toch werken in het donker, verlicht alleen de werkplek en voorkom uitstraling naar de omgeving | C12: Materieel en methode | D12: uitvoering
A13: A8 | B13: Gebruik een klepelmaaier alleen volgens de vastgestelde uitzonderingen zoals beschreven in bijlage 7 van de gedragscode. | C13: Materieel en methode | D13: uitvoering
... A19: A14 | B19: Voer maaisel/schoonsel binnen afgesproken termijn af. | C19: Vrijkomende materialen | D19: uitvoering
A20: A15 | B20: Maaiboot met sleepmes is alleen toegestaan in overleg met HHSK. | C20: Materieel en methode | D20: uitvoering | E20: JA
A21: A16 | B21: AANVULLEN inventariseer belangrijke groeiplaatsen van planten die de waterkwaliteit, biodiversiteit bevorderen, zoals zwanenbloem, rietorchis, moeraswespenorchis en markeer deze digitaal en in het veld | C21: Soort- en habitatbescherming | D21: voorbereiding | E21: JA
A22: A17 | B22: Blijf met maaimachines minimaal 0,5 m uit de stamvoet van bomen | C22: Materieel en methode | D22: uitvoering | E22: JA
A23: A18 | B23: Leg geen materiaal op gespaarde vegetatie of op/in holen | C23: Vrijkomende materialen | D23: uitvoering | E23: JA
A24: A19 | B24: Spaar de belangrijke groeiplaatsen van planten zoals zwanenbloem, rietorchis, moeraswespenorchis. Deze staan op de onderhoudskaart of in de MaaiApp. Rijd er niet overheen | C24: Soort- en habitatbescherming | D24: uitvoering | E24: JA
A25: A20 | B25: Werk van binnen naar buiten | C25: Materieel en methode | D25: uitvoering
A26: A21 | B26: Gebruik waar nodig faunavriendelijke hulpmiddelen (bijv. wildredder). | C26: Materieel en methode | D26: uitvoering
A27: A22 | B27: Beperk beroering van bodem en water | C27: Materieel en methode | D27: uitvoering
A28: A23 | B28: Voorkom dat materiaal terug de watergang in valt/glijdt | C28: Materieel en methode | D28: uitvoering
A29: A24 | B29: Stop werk bij: watertemperaturen < 5°C en > 25 °C | C29: Soort- en habitatbescherming | D29: uitvoering
A30: A25 | B30: Stop werk bij: zuurstof < 4 mg/l, slome of happende vissen | C30: Soort- en habitatbescherming | D30: uitvoering
A31: A26 | B31: Stamhout en grote takken mogen op rillen in de houtopstand achterblijven tenzij daar beschermde planten of dieren zitten. Voer takken en versnipperd hout af. | C31: Vrijkomende materialen | D31: uitvoering
A32: A27 | B32: AANVULLEN: Natuurvriendelijke materieel wordt ingezet op die plekken waar de ecologische winst het grootste is. De ecologische deskundig kan hierin begeleiden. | C32: Materieel en methode | D32: uitvoering
A33: A28 | B33: AANVULLEN: Werk buiten migratieperioden (indicatief: mrt–apr en sep–half nov). | C33: Soort- en habitatbescherming | D33: voorbereiding
A34: A29 | B34: AANVULLEN: Houd geleidingsschermen vrij van overhangende planten en toegankelijk voor fauna. De ecologisch deskundige bepaald de intensiteit van het onderhoud van geleidingsschermen voor amfibiën. Deze zal afhankelijk zijn van de bodem en vegetatietypen. | C34: Soort- en habitatbescherming | D34: voorbereiding
A35: A30 | B35: Indien er delen overstroomd zijn geweest (na hoog water), wordt er voorafgaand de werkzaamheden een controle uitgevoerd op aanwezige dieren. Bij het aantreffen worden de dieren teruggeplaatst in de watergang. | C35: Soort- en habitatbescherming | D35: voorbereiding
A36: S5 | B36: Werkzaamheden dienen te worden uitgevoerd buiten de actieve periode van de soort. Globaal is de werkperiode van oktober t/m maart. De exacte periode dient te worden bepaald door een ecologisch deskundige. | C36: Schonen | D36: uitvoering
... A40: S9 | B40: AANVULLEN: Bepaal of de active periode van de rugstreeppad afwijkt van maart t/m oktober. Zo ja, pas dan de uitvoeringsperiode aan in het UP. | C40: Maaien | D40: voorbereiding
A41: S10 | B41: Werkzaamheden gefaseerd uitvoeren. Pas extensief en gefaseerd beheer toe door maximaal 50% per jaar grasland te bewerken. Elk jaar een ander deel laten staan. Uitgangspunten: behoud structuurvariatie, markeer en ontzie aanwezige voortplantingsplaatsenen. | C41: Maaien | D41: uitvoering | E41: JA
A42: S11 | B42: AANVULLEN: Bij aantoonbare noodzaak (met wettelijk belang en alternatievenafweging) productieve vegetaties op rijke gronden een 2e keer maaien, met minimaal zes weken tussen de maaibeurten, waardoor in fasering 100% gemaaid is. De noodzaak hiertoe dient door een ecologisch deskundige goed onderbouwd in het ecologisch werkprotocol te worden opgenomen. | C42: Maaien | D42: voorbereiding | E42: JA
A43: S12 | B43: AANVULLEN: De ecologisch deskundige bepaalt de broedperiode voor de projectspecifieke locatie. Bijvoorbeeld 1 februari t/m 31 oktober. | C43: Maaien | D43: voorbereiding
A44: S13 | B44: Indien er binnen de broedperiode van vogels wordt gewerkt, is een locatiebezoek van een ecologisch deskundige nodig. Registreer, markeer en spaar actieve nesten. Spaar minimaal 10 meter vegetatie rond een nest en houdt rekening met voldoende voedsel en dekking voor de jonge vogels. | C44: Maaien | D44: uitvoering
A45: S14 | B45: Raadpleeg de GIS -kaart voor de exacte locaties en begrenzingen van essentieel leefgebied en burchten van bever. Zijn er geen burchten of essentieel leefgebied bekend op de specifieke projectlocatie? Dan zijn er geen maatregelen benodigd. Zijn er wel burchten of essentieel leefgebied bekend op de specifieke projectlocatie, schakel dan een beverdeskundige in en pas de maatregelen toe op pagina 43 van de GC. De volgende uitgangspunten gelden: 1.Er worden geen werkzaamheden uitgevoerd in het essentiële leefgebied van bever. Bij aanwezigheid van rust - en voortplantingsplaatsen worden de werkzaamheden uitgevoerd in de periode van september tot en met april. Er mag niet gewerkt worden vanaf de oever waarin zich een hol of burcht bevindt, in de periode net voor en na de zonsondergang dan wel zonsopkomst of bij ijsgang. 2.De beschermingszone en aanpak op basis van behoud van functionaliteit dienen te worden bepaald door de ecologisch deskundige. Buiten de kwetsbare periode (sept – april): indien de werkzaamheden met handkracht worden uitgevoerd zijn de werkzaamheden binnen de beschermingszone toegestaan. Binnen de kwetsbare periode (mei – aug): de werkzaamheden binnen 20 meter van een beverburcht zijn uitsluitend toegestaan wanneer een ecologisch deskundige onderbouwd heeft aangegeven dat hiervan geen verstorende werking uitgaat. 3.Werkzaamheden worden overdag uitgevoerd. 4. Het beheer dient gericht te zijn op behoud van de leefomgeving door gefaseerd te werken in tijd in ruimte met behoud van essentiëlefoerageerlocaties. | C45: Maaien | D45: voorbereiding
A46: S15 | B46: Voer de maaiwerkzaamhedenuit in de winterrustperiode, dit is van oktober tot en met maart. Indien de werkzaamheden in de actieve periode (april tot en met september) worden uitgevoerd, dan alleen maaien bij een temperatuur boven de 15°C , zodat dieren kunnen vluchten. Broeihopen altijd sparen. | C46: Maaien | D46: uitvoering | E46: JA
A47: S16 | B47: Voorafgaand aan de schoningswerkzaamheden in bestaand leefgebied dient door een ecologisch deskundige te worden beoordeeld of uitvoering hiervan in betreffende watergang noodzakelijk is. | C47: Schonen | D47: voobereiding | E47: JA
A48: S17 | B48: Voorafgaand aan de schoningswerkzaamheden in bestaand leefgebied dient door een ecologisch deskundige te worden beoordeeld of uitvoering hiervan in betreffende watergang noodzakelijk is. | C48: Schonen | D48: uitvoering | E48: JA
...

Sheet soorten
A1: soort | B1: soortgroep | C1: beschermingscategorie
A2: Argusvlinder | B2: Vlinders | C2: Icoonsoort
A3: Bever | B3: Zoogdieren grondgebonden | C3: HR
A4: Boerenzwaluw | B4: Vogels | C4: VR
A5: Boommarter | B5: Zoogdieren grondgebonden | C5: Andere soort
A6: Gestreepte waterroofkever | B6: Insecten | C6: HR
A7: Gevlekte witsnuitlibel | B7: Libellen | C7: HR
A8: Gewone dwergvleermuis | B8: Vleermuizen | C8: HR
A9: Gewone grootoorvleermuis | B9: Vleermuizen | C9: HR
A10: Groene glazenmaker | B10: Libellen | C10: HR
A11: Groot leermos | B11: Korstmossen | C11: Specifieke zorgplicht
A12: Grote gele kwikstaart | B12: Vogels | C12: VR
... A40: Zwarte stern | B40: Vogels | C40: VR

Sheet gebied_soorten
A1: gebied_code | B1: gebied_omschrijving | C1: subgebied_omschrijving | D1: soort
A2: KO | B2: =IF(A2="","",VLOOKUP($A2,gebieden!$A$2:$B$56,2,FALSE)) -> Krimpenerwaard oost | D2: Rugstreeppad
A3: KO | B3: =IF(A3="","",VLOOKUP($A3,gebieden!$A$2:$B$56,2,FALSE)) -> Krimpenerwaard oost | D3: Heikikker
A4: KO | B4: =IF(A4="","",VLOOKUP($A4,gebieden!$A$2:$B$56,2,FALSE)) -> Krimpenerwaard oost | D4: Waterspitsmuis
A5: KO | B5: =IF(A5="","",VLOOKUP($A5,gebieden!$A$2:$B$56,2,FALSE)) -> Krimpenerwaard oost | D5: Platte schijfhoren
A6: KO | B6: =IF(A6="","",VLOOKUP($A6,gebieden!$A$2:$B$56,2,FALSE)) -> Krimpenerwaard oost | D6: Boerenzwaluw
A7: KO | B7: =IF(A7="","",VLOOKUP($A7,gebieden!$A$2:$B$56,2,FALSE)) -> Krimpenerwaard oost | D7: Argusvlinder
A8: KO | B8: =IF(A8="","",VLOOKUP($A8,gebieden!$A$2:$B$56,2,FALSE)) -> Krimpenerwaard oost | C8: SB | D8: Bever
A9: KO | B9: =IF(A9="","",VLOOKUP($A9,gebieden!$A$2:$B$56,2,FALSE)) -> Krimpenerwaard oost | C9: SB | D9: Waterspitsmuis
A10: KO | B10: =IF(A10="","",VLOOKUP($A10,gebieden!$A$2:$B$56,2,FALSE)) -> Krimpenerwaard oost | C10: SB | D10: Schele engerd
A11: KO | B11: =IF(A11="","",VLOOKUP($A11,gebieden!$A$2:$B$56,2,FALSE)) -> Krimpenerwaard oost | C11: LT | D11: Platte schijfhoren
A12: KO | B12: =IF(A12="","",VLOOKUP($A12,gebieden!$A$2:$B$56,2,FALSE)) -> Krimpenerwaard oost | C12: LT | D12: Boerenzwaluw
A13: KO | B13: =IF(A13="","",VLOOKUP($A13,gebieden!$A$2:$B$56,2,FALSE)) -> Krimpenerwaard oost | C13: AS | D13: Steenuil (essentieel leefgebied)
A14: KO | B14: =IF(A14="","",VLOOKUP($A14,gebieden!$A$2:$B$56,2,FALSE)) -> Krimpenerwaard oost | C14: BW | D14: Vleermuizen (essentiele vliegroute)
A15: KO | B15: =IF(A15="","",VLOOKUP($A15,gebieden!$A$2:$B$56,2,FALSE)) -> Krimpenerwaard oost | C15: FK | D15: Vleermuizen (essentiele vliegroute)
A16: KW | B16: =IF(A16="","",VLOOKUP($A16,gebieden!$A$2:$B$56,2,FALSE)) -> Krimpenerwaard west | D16: Boerenzwaluw
A17: KW | B17: =IF(A17="","",VLOOKUP($A17,gebieden!$A$2:$B$56,2,FALSE)) -> Krimpenerwaard west | D17: Argusvlinder
A18: KW | B18: =IF(A18="","",VLOOKUP($A18,gebieden!$A$2:$B$56,2,FALSE)) -> Krimpenerwaard west | C18: OU | D18: Stinkende kamille
A19: KW | B19: =IF(A19="","",VLOOKUP($A19,gebieden!$A$2:$B$56,2,FALSE)) -> Krimpenerwaard west | C19: NT | D19: Groene glazenmaker
A20: KW | B20: =IF(A20="","",VLOOKUP($A20,gebieden!$A$2:$B$56,2,FALSE)) -> Krimpenerwaard west | C20: BL | D20: Zwarte stern
A21: KW | B21: =IF(A21="","",VLOOKUP($A21,gebieden!$A$2:$B$56,2,FALSE)) -> Krimpenerwaard west | C21: BH | D21: Groene glazenmaker
A22: KW | B22: =IF(A22="","",VLOOKUP($A22,gebieden!$A$2:$B$56,2,FALSE)) -> Krimpenerwaard west | C22: BH | D22: Platte schijfhoren
A23: KW | B23: =IF(A23="","",VLOOKUP($A23,gebieden!$A$2:$B$56,2,FALSE)) -> Krimpenerwaard west | C23: BH | D23: Schele engerd
A24: KW | B24: =IF(A24="","",VLOOKUP($A24,gebieden!$A$2:$B$56,2,FALSE)) -> Krimpenerwaard west | C24: GR | D24: Roodrandzandbij
A25: KW | B25: =IF(A25="","",VLOOKUP($A25,gebieden!$A$2:$B$56,2,FALSE)) -> Krimpenerwaard west | C25: GR | D25: Veldkruidkers
A26: SN | B26: =IF(A26="","",VLOOKUP($A26,gebieden!$A$2:$B$56,2,FALSE)) -> Schieland noord
A27: SN | B27: =IF(A27="","",VLOOKUP($A27,gebieden!$A$2:$B$56,2,FALSE)) -> Schieland noord | C27: EP | D27: Naakte lathyrus
A28: SN | B28: =IF(A28="","",VLOOKUP($A28,gebieden!$A$2:$B$56,2,FALSE)) -> Schieland noord | C28: EP | D28: Platte schijfhoren
A29: SN | B29: =IF(A29="","",VLOOKUP($A29,gebieden!$A$2:$B$56,2,FALSE)) -> Schieland noord | C29: GZ | D29: Rugstreeppad
A30: SN | B30: =IF(A30="","",VLOOKUP($A30,gebieden!$A$2:$B$56,2,FALSE)) -> Schieland noord | C30: ZP | D30: Ringslang
A31: SN | B31: =IF(A31="","",VLOOKUP($A31,gebieden!$A$2:$B$56,2,FALSE)) -> Schieland noord | C31: ZP | D31: Waterspitsmuis
A32: SN | B32: =IF(A32="","",VLOOKUP($A32,gebieden!$A$2:$B$56,2,FALSE)) -> Schieland noord | C32: ZP | D32: Platte schijfhoren
A33: SN | B33: =IF(A33="","",VLOOKUP($A33,gebieden!$A$2:$B$56,2,FALSE)) -> Schieland noord | C33: GL | D33: Roodrandzandbij
A34: SZ | B34: =IF(A34="","",VLOOKUP($A34,gebieden!$A$2:$B$56,2,FALSE)) -> Schieland zuid incl. Krimpen a/d Ijssel
A35: SZ | B35: =IF(A35="","",VLOOKUP($A35,gebieden!$A$2:$B$56,2,FALSE)) -> Schieland zuid incl. Krimpen a/d Ijssel | C35: KV | D35: Muurtrechterje
A36: SZ | B36: =IF(A36="","",VLOOKUP($A36,gebieden!$A$2:$B$56,2,FALSE)) -> Schieland zuid incl. Krimpen a/d Ijssel | C36: KV | D36: Groot leermos
A37: SZ | B37: =IF(A37="","",VLOOKUP($A37,gebieden!$A$2:$B$56,2,FALSE)) -> Schieland zuid incl. Krimpen a/d Ijssel | C37: IJN | D37: Ruige leeuwentand
A38: SZ | B38: =IF(A38="","",VLOOKUP($A38,gebieden!$A$2:$B$56,2,FALSE)) -> Schieland zuid incl. Krimpen a/d Ijssel | C38: IJN | D38: Karweivarkenskervel
A39: SZ | B39: =IF(A39="","",VLOOKUP($A39,gebieden!$A$2:$B$56,2,FALSE)) -> Schieland zuid incl. Krimpen a/d Ijssel | C39: BK | D39: Stinkende kamille
A40: KO | B40: =IF(A40="","",VLOOKUP($A40,gebieden!$A$2:$B$56,2,FALSE)) -> Krimpenerwaard oost | D40: Vogels
...

Sheet algemene_maatregelen
A1: werk_code | B1: werk_omschrijving | C1: maatregel_code | D1: maatregel_omschrijving
A2: 1a | B2: =IF($A2="","",VLOOKUP($A2,werkzaamheden!$A$2:$B$170,2,FALSE)) -> Schonen wateren en maaien oevers - Schieland en Krimpen ad IJssel | C2: A1 | D2: =IF($C2="","",VLOOKUP($C2,maatregelen!$A$2:$B$1043,2,FALSE)) -> Voorkom insporing en beschadiging van bermen, oevers en beplanting (max. insporing 5 cm).
A3: 1a | B3: =IF($A3="","",VLOOKUP($A3,werkzaamheden!$A$2:$B$170,2,FALSE)) -> Schonen wateren en maaien oevers - Schieland en Krimpen ad IJssel | C3: A2 | D3: =IF($C3="","",VLOOKUP($C3,maatregelen!$A$2:$B$1043,2,FALSE)) -> Rijd of vaar stapvoets (< 5 km/u).
A4: 1a | B4: =IF($A4="","",VLOOKUP($A4,werkzaamheden!$A$2:$B$170,2,FALSE)) -> Schonen wateren en maaien oevers - Schieland en Krimpen ad IJssel | C4: A3 | D4: =IF($C4="","",VLOOKUP($C4,maatregelen!$A$2:$B$1043,2,FALSE)) -> Let altijd op alarmerende vogels en hun nesten. Nest gevonden? Stop en pas het werk aan. Houd 10 meter afstand tot het nest; Meld en registreer het nest.
A5: 1a | B5: =IF($A5="","",VLOOKUP($A5,werkzaamheden!$A$2:$B$170,2,FALSE)) -> Schonen wateren en maaien oevers - Schieland en Krimpen ad IJssel | C5: A4 | D5: =IF($C5="","",VLOOKUP($C5,maatregelen!$A$2:$B$1043,2,FALSE)) -> Werk richting een rustig gebied waar dieren kunnen ontsnappen
A6: 1a | B6: =IF($A6="","",VLOOKUP($A6,werkzaamheden!$A$2:$B$170,2,FALSE)) -> Schonen wateren en maaien oevers - Schieland en Krimpen ad IJssel | C6: A5 | D6: =IF($C6="","",VLOOKUP($C6,maatregelen!$A$2:$B$1043,2,FALSE)) -> Maai minimaal 10 cm boven bodem of waterbodem
A7: 1a | B7: =IF($A7="","",VLOOKUP($A7,werkzaamheden!$A$2:$B$170,2,FALSE)) -> Schonen wateren en maaien oevers - Schieland en Krimpen ad IJssel | C7: A6 | D7: =IF($C7="","",VLOOKUP($C7,maatregelen!$A$2:$B$1043,2,FALSE)) -> Gebruik waar mogelijk lage bandenspanning of andere bodemsparende technieken. Pas dit altijd toe op natte of kwetsbare plekken.
A8: 1a | B8: =IF($A8="","",VLOOKUP($A8,werkzaamheden!$A$2:$B$170,2,FALSE)) -> Schonen wateren en maaien oevers - Schieland en Krimpen ad IJssel | C8: A7 | D8: =IF($C8="","",VLOOKUP($C8,maatregelen!$A$2:$B$1043,2,FALSE)) -> Werk overdag. Moet je toch werken in het donker, verlicht alleen de werkplek en voorkom uitstraling naar de omgeving
A9: 1a | B9: =IF($A9="","",VLOOKUP($A9,werkzaamheden!$A$2:$B$170,2,FALSE)) -> Schonen wateren en maaien oevers - Schieland en Krimpen ad IJssel | C9: A8 | D9: =IF($C9="","",VLOOKUP($C9,maatregelen!$A$2:$B$1043,2,FALSE)) -> Gebruik een klepelmaaier alleen volgens de vastgestelde uitzonderingen zoals beschreven in bijlage 7 van de gedragscode.
A10: 1a | B10: =IF($A10="","",VLOOKUP($A10,werkzaamheden!$A$2:$B$170,2,FALSE)) -> Schonen wateren en maaien oevers - Schieland en Krimpen ad IJssel | C10: A9 | D10: =IF($C10="","",VLOOKUP($C10,maatregelen!$A$2:$B$1043,2,FALSE)) -> Vermijd het raken van het natte profiel van de waterbodem. Werk bijvoorbeeld niet in ondiep water met een boot met schroef of jetvoortstuwing.
A11: 1a | B11: =IF($A11="","",VLOOKUP($A11,werkzaamheden!$A$2:$B$170,2,FALSE)) -> Schonen wateren en maaien oevers - Schieland en Krimpen ad IJssel | C11: A10 | D11: =IF($C11="","",VLOOKUP($C11,maatregelen!$A$2:$B$1043,2,FALSE)) -> Gebruik tenminste één techniek om slachtoffers te voorkomen. Bijvoorbeeld: vooraf de korf op het water slaan, terugkorven, de laatste 10 meter voor een duiker overslaan en vanaf de duiker terugwerken, gebruik maken van een maaikorf met open spijlen (niet met dichte bak) en niet breder dan 6 meter.
A12: 1a | B12: =IF($A12="","",VLOOKUP($A12,werkzaamheden!$A$2:$B$170,2,FALSE)) -> Schonen wateren en maaien oevers - Schieland en Krimpen ad IJssel | C12: A11 | D12: =IF($C12="","",VLOOKUP($C12,maatregelen!$A$2:$B$1043,2,FALSE)) -> Leg maaisel, schoonsel of bagger op of langs het onderhoudspad. Anders buiten de insteek. Hou rekening met ontvangstplicht
A13: 1a | B13: =IF($A13="","",VLOOKUP($A13,werkzaamheden!$A$2:$B$170,2,FALSE)) -> Schonen wateren en maaien oevers - Schieland en Krimpen ad IJssel | C13: A12 | D13: =IF($C13="","",VLOOKUP($C13,maatregelen!$A$2:$B$1043,2,FALSE)) -> AANVULLEN: Gebruik natuurvriendelijk materieel. Tip: benut de veldgids ecologisch slootbeheer voor selectie van de beste passende machine.
... A88: 2d | B88: =IF($A88="","",VLOOKUP($A88,werkzaamheden!$A$2:$B$170,2,FALSE)) -> Maaien eigen terreinen en rond kunstwerken | C88: A18 | D88: =IF($C88="","",VLOOKUP($C88,maatregelen!$A$2:$B$1043,2,FALSE)) -> Leg geen materiaal op gespaarde vegetatie of op/in holen
A89: 3 | B89: =IF($A89="","",VLOOKUP($A89,werkzaamheden!$A$2:$B$170,2,FALSE)) -> Baggeren van wateren (onderhoud) | C89: A1 | D89: =IF($C89="","",VLOOKUP($C89,maatregelen!$A$2:$B$1043,2,FALSE)) -> Voorkom insporing en beschadiging van bermen, oevers en beplanting (max. insporing 5 cm).
A90: 3 | B90: =IF($A90="","",VLOOKUP($A90,werkzaamheden!$A$2:$B$170,2,FALSE)) -> Baggeren van wateren (onderhoud) | C90: A2 | D90: =IF($C90="","",VLOOKUP($C90,maatregelen!$A$2:$B$1043,2,FALSE)) -> Rijd of vaar stapvoets (< 5 km/u).
A91: 3 | B91: =IF($A91="","",VLOOKUP($A91,werkzaamheden!$A$2:$B$170,2,FALSE)) -> Baggeren van wateren (onderhoud) | C91: A3 | D91: =IF($C91="","",VLOOKUP($C91,maatregelen!$A$2:$B$1043,2,FALSE)) -> Let altijd op alarmerende vogels en hun nesten. Nest gevonden? Stop en pas het werk aan. Houd 10 meter afstand tot het nest; Meld en registreer het nest.
A92: 3 | B92: =IF($A92="","",VLOOKUP($A92,werkzaamheden!$A$2:$B$170,2,FALSE)) -> Baggeren van wateren (onderhoud) | C92: A4 | D92: =IF($C92="","",VLOOKUP($C92,maatregelen!$A$2:$B$1043,2,FALSE)) -> Werk richting een rustig gebied waar dieren kunnen ontsnappen
A93: 3 | B93: =IF($A93="","",VLOOKUP($A93,werkzaamheden!$A$2:$B$170,2,FALSE)) -> Baggeren van wateren (onderhoud) | C93: A6 | D93: =IF($C93="","",VLOOKUP($C93,maatregelen!$A$2:$B$1043,2,FALSE)) -> Gebruik waar mogelijk lage bandenspanning of andere bodemsparende technieken. Pas dit altijd toe op natte of kwetsbare plekken.
A94: 3 | B94: =IF($A94="","",VLOOKUP($A94,werkzaamheden!$A$2:$B$170,2,FALSE)) -> Baggeren van wateren (onderhoud) | C94: A7 | D94: =IF($C94="","",VLOOKUP($C94,maatregelen!$A$2:$B$1043,2,FALSE)) -> Werk overdag. Moet je toch werken in het donker, verlicht alleen de werkplek en voorkom uitstraling naar de omgeving
A95: 3 | B95: =IF($A95="","",VLOOKUP($A95,werkzaamheden!$A$2:$B$170,2,FALSE)) -> Baggeren van wateren (onderhoud) | C95: A11 | D95: =IF($C95="","",VLOOKUP($C95,maatregelen!$A$2:$B$1043,2,FALSE)) -> Leg maaisel, schoonsel of bagger op of langs het onderhoudspad. Anders buiten de insteek. Hou rekening met ontvangstplicht
A96: 3 | B96: =IF($A96="","",VLOOKUP($A96,werkzaamheden!$A$2:$B$170,2,FALSE)) -> Baggeren van wateren (onderhoud) | C96: A12 | D96: =IF($C96="","",VLOOKUP($C96,maatregelen!$A$2:$B$1043,2,FALSE)) -> AANVULLEN: Gebruik natuurvriendelijk materieel. Tip: benut de veldgids ecologisch slootbeheer voor selectie van de beste passende machine.
A97: 3 | B97: =IF($A97="","",VLOOKUP($A97,werkzaamheden!$A$2:$B$170,2,FALSE)) -> Baggeren van wateren (onderhoud) | C97: A13 | D97: =IF($C97="","",VLOOKUP($C97,maatregelen!$A$2:$B$1043,2,FALSE)) -> AANVULLEN: Gebruik materiaal met een ‘rode’ score (tabel 16/17 - veldgids ecologisch slootbeheer) alleen als gebruik ervan is onderbouwd door een ecologisch deskundige
A98: 3 | B98: =IF($A98="","",VLOOKUP($A98,werkzaamheden!$A$2:$B$170,2,FALSE)) -> Baggeren van wateren (onderhoud) | C98: A16 | D98: =IF($C98="","",VLOOKUP($C98,maatregelen!$A$2:$B$1043,2,FALSE)) -> AANVULLEN inventariseer belangrijke groeiplaatsen van planten die de waterkwaliteit, biodiversiteit bevorderen, zoals zwanenbloem, rietorchis, moeraswespenorchis en markeer deze digitaal en in het veld
A99: 3 | B99: =IF($A99="","",VLOOKUP($A99,werkzaamheden!$A$2:$B$170,2,FALSE)) -> Baggeren van wateren (onderhoud) | C99: A19 | D99: =IF($C99="","",VLOOKUP($C99,maatregelen!$A$2:$B$1043,2,FALSE)) -> Spaar de belangrijke groeiplaatsen van planten zoals zwanenbloem, rietorchis, moeraswespenorchis. Deze staan op de onderhoudskaart of in de MaaiApp. Rijd er niet overheen
A100: 3 | B100: =IF($A100="","",VLOOKUP($A100,werkzaamheden!$A$2:$B$170,2,FALSE)) -> Baggeren van wateren (onderhoud) | C100: A22 | D100: =IF($C100="","",VLOOKUP($C100,maatregelen!$A$2:$B$1043,2,FALSE)) -> Beperk beroering van bodem en water
... A124: 5 | B124: =IF($A124="","",VLOOKUP($A124,werkzaamheden!$A$2:$B$170,2,FALSE)) -> Onderhoud aan waterkeringen, duikers, kaden en kunstwerken | C124: A30 | D124: =IF($C124="","",VLOOKUP($C124,maatregelen!$A$2:$B$1043,2,FALSE)) -> Indien er delen overstroomd zijn geweest (na hoog water), wordt er voorafgaand de werkzaamheden een controle uitgevoerd op aanwezige dieren. Bij het aantreffen worden de dieren teruggeplaatst in de watergang.
B125: =IF($A125="","",VLOOKUP($A125,werkzaamheden!$A$2:$B$170,2,FALSE)) | D125: =IF($C125="","",VLOOKUP($C125,maatregelen!$A$2:$B$1043,2,FALSE))
B126: =IF($A126="","",VLOOKUP($A126,werkzaamheden!$A$2:$B$170,2,FALSE)) | D126: =IF($C126="","",VLOOKUP($C126,maatregelen!$A$2:$B$1043,2,FALSE))
B127: =IF($A127="","",VLOOKUP($A127,werkzaamheden!$A$2:$B$170,2,FALSE)) | D127: =IF($C127="","",VLOOKUP($C127,maatregelen!$A$2:$B$1043,2,FALSE))
B128: =IF($A128="","",VLOOKUP($A128,werkzaamheden!$A$2:$B$170,2,FALSE)) | D128: =IF($C128="","",VLOOKUP($C128,maatregelen!$A$2:$B$1043,2,FALSE))
B129: =IF($A129="","",VLOOKUP($A129,werkzaamheden!$A$2:$B$170,2,FALSE)) | D129: =IF($C129="","",VLOOKUP($C129,maatregelen!$A$2:$B$1043,2,FALSE))
B130: =IF($A130="","",VLOOKUP($A130,werkzaamheden!$A$2:$B$170,2,FALSE)) | D130: =IF($C130="","",VLOOKUP($C130,maatregelen!$A$2:$B$1043,2,FALSE))
B131: =IF($A131="","",VLOOKUP($A131,werkzaamheden!$A$2:$B$170,2,FALSE)) | D131: =IF($C131="","",VLOOKUP($C131,maatregelen!$A$2:$B$1043,2,FALSE))
B132: =IF($A132="","",VLOOKUP($A132,werkzaamheden!$A$2:$B$170,2,FALSE)) | D132: =IF($C132="","",VLOOKUP($C132,maatregelen!$A$2:$B$1043,2,FALSE))
B133: =IF($A133="","",VLOOKUP($A133,werkzaamheden!$A$2:$B$170,2,FALSE)) | D133: =IF($C133="","",VLOOKUP($C133,maatregelen!$A$2:$B$1043,2,FALSE))
B134: =IF($A134="","",VLOOKUP($A134,werkzaamheden!$A$2:$B$170,2,FALSE)) | D134: =IF($C134="","",VLOOKUP($C134,maatregelen!$A$2:$B$1043,2,FALSE))
B135: =IF($A135="","",VLOOKUP($A135,werkzaamheden!$A$2:$B$170,2,FALSE)) | D135: =IF($C135="","",VLOOKUP($C135,maatregelen!$A$2:$B$1043,2,FALSE))
B136: =IF($A136="","",VLOOKUP($A136,werkzaamheden!$A$2:$B$170,2,FALSE)) | D136: =IF($C136="","",VLOOKUP($C136,maatregelen!$A$2:$B$1043,2,FALSE))
... B10000: =IF($A10000="","",VLOOKUP($A10000,werkzaamheden!$A$2:$B$170,2,FALSE)) | D10000: =IF($C10000="","",VLOOKUP($C10000,maatregelen!$A$2:$B$1043,2,FALSE))

Sheet soortspecifieke_maatregelen
A1: soort | B1: werk_code | C1: werk_omschrijving | D1: periode_begin | E1: periode_eind | F1: maatregel_code | G1: maatregel_omschrijving
A2: Naakte lathyrus | B2: 1a | C2: =IF($B2="","",VLOOKUP($B2,werkzaamheden!$A$2:$B$170,2,FALSE)) -> Schonen wateren en maaien oevers - Schieland en Krimpen ad IJssel | D2: 46143 | E2: 46295 | F2: S1 | G2: =IF($F2="","",VLOOKUP($F2,maatregelen!$A$2:$B$1043,2,FALSE)) -> Maaien voor mei en/of vanaf september vanwege de zaadzetting.
A3: Naakte lathyrus | B3: 1a | C3: =IF($B3="","",VLOOKUP($B3,werkzaamheden!$A$2:$B$170,2,FALSE)) -> Schonen wateren en maaien oevers - Schieland en Krimpen ad IJssel | D3: 46143 | E3: 46295 | F3: S2 | G3: =IF($F3="","",VLOOKUP($F3,maatregelen!$A$2:$B$1043,2,FALSE)) -> Groeiplaatsen van beschermde plantensoorten worden ontzien bij rijbewegingen en bij tijdelijke opslag van materieel.
A4: Naakte lathyrus | B4: 1a | C4: =IF($B4="","",VLOOKUP($B4,werkzaamheden!$A$2:$B$170,2,FALSE)) -> Schonen wateren en maaien oevers - Schieland en Krimpen ad IJssel | D4: 46143 | E4: 46295 | F4: S3 | G4: =IF($F4="","",VLOOKUP($F4,maatregelen!$A$2:$B$1043,2,FALSE)) -> Schakel een ecologisch deskundige in op het gebied van planten om groeiplaatsen te markeren en een werkinstructie voor het maaien te ontvangen.
A5: Naakte lathyrus | B5: 1a | C5: =IF($B5="","",VLOOKUP($B5,werkzaamheden!$A$2:$B$170,2,FALSE)) -> Schonen wateren en maaien oevers - Schieland en Krimpen ad IJssel | D5: 46143 | E5: 46295 | F5: S4 | G5: =IF($F5="","",VLOOKUP($F5,maatregelen!$A$2:$B$1043,2,FALSE)) -> Het maaibeheer is vastgelegd in een beheerplan.
A6: Rugstreeppad | B6: 1a | C6: =IF($B6="","",VLOOKUP($B6,werkzaamheden!$A$2:$B$170,2,FALSE)) -> Schonen wateren en maaien oevers - Schieland en Krimpen ad IJssel | D6: 46296 | E6: 46081 | F6: S5 | G6: =IF($F6="","",VLOOKUP($F6,maatregelen!$A$2:$B$1043,2,FALSE)) -> Werkzaamheden dienen te worden uitgevoerd buiten de actieve periode van de soort. Globaal is de werkperiode van oktober t/m maart. De exacte periode dient te worden bepaald door een ecologisch deskundige.
A7: Rugstreeppad | B7: 1a | C7: =IF($B7="","",VLOOKUP($B7,werkzaamheden!$A$2:$B$170,2,FALSE)) -> Schonen wateren en maaien oevers - Schieland en Krimpen ad IJssel | D7: 46296 | E7: 46081 | F7: S6 | G7: =IF($F7="","",VLOOKUP($F7,maatregelen!$A$2:$B$1043,2,FALSE)) -> AANVULLEN: Bepaal of de active periode van de rugstreeppad afwijkt van maart t/m oktober. Zo ja, pas dan de uitvoeringsperiode aan in het UP.
A8: Rugstreeppad | B8: 1a | C8: =IF($B8="","",VLOOKUP($B8,werkzaamheden!$A$2:$B$170,2,FALSE)) -> Schonen wateren en maaien oevers - Schieland en Krimpen ad IJssel | D8: 46296 | E8: 46081 | F8: S7 | G8: =IF($F8="","",VLOOKUP($F8,maatregelen!$A$2:$B$1043,2,FALSE)) -> In essentieel leefgebied wordt gefaseerd gewerkt: minimaal 30% per jaar sparen. Elk jaar een ander deel laten staan. Verder geldt dat de werkzaamheden met behoud van locaties waar overwintering plaats vindt (plekken met pollen, holen, hopen, stronken en takkenrillen) worden uitgevoerd. Het beheer dient gericht te zijn op behoud van schuilmogelijkheden en dekking, afgewisseld met open plekken om te zonnen, dit door kleinschalig te werken, bijvoorbeeld in stroken.
A9: Rugstreeppad | B9: 1a | C9: =IF($B9="","",VLOOKUP($B9,werkzaamheden!$A$2:$B$170,2,FALSE)) -> Schonen wateren en maaien oevers - Schieland en Krimpen ad IJssel | D9: 46296 | E9: 46081 | F9: S8 | G9: =IF($F9="","",VLOOKUP($F9,maatregelen!$A$2:$B$1043,2,FALSE)) -> Werkzaamheden dienen te worden uitgevoerd buiten de actieve periode van de soort. Globaal is de werkperiode van oktober t/m maart. De exacte periode dient te worden bepaald door een ecologisch deskundige.
A10: Rugstreeppad | B10: 1a | C10: =IF($B10="","",VLOOKUP($B10,werkzaamheden!$A$2:$B$170,2,FALSE)) -> Schonen wateren en maaien oevers - Schieland en Krimpen ad IJssel | D10: 46296 | E10: 46081 | F10: S9 | G10: =IF($F10="","",VLOOKUP($F10,maatregelen!$A$2:$B$1043,2,FALSE)) -> AANVULLEN: Bepaal of de active periode van de rugstreeppad afwijkt van maart t/m oktober. Zo ja, pas dan de uitvoeringsperiode aan in het UP.
A11: Rugstreeppad | B11: 1a | C11: =IF($B11="","",VLOOKUP($B11,werkzaamheden!$A$2:$B$170,2,FALSE)) -> Schonen wateren en maaien oevers - Schieland en Krimpen ad IJssel | D11: 46082 | E11: 46295 | F11: S10 | G11: =IF($F11="","",VLOOKUP($F11,maatregelen!$A$2:$B$1043,2,FALSE)) -> Werkzaamheden gefaseerd uitvoeren. Pas extensief en gefaseerd beheer toe door maximaal 50% per jaar grasland te bewerken. Elk jaar een ander deel laten staan. Uitgangspunten: behoud structuurvariatie, markeer en ontzie aanwezige voortplantingsplaatsenen.
A12: Rugstreeppad | B12: 1a | C12: =IF($B12="","",VLOOKUP($B12,werkzaamheden!$A$2:$B$170,2,FALSE)) -> Schonen wateren en maaien oevers - Schieland en Krimpen ad IJssel | D12: 46082 | E12: 46295 | F12: S11 | G12: =IF($F12="","",VLOOKUP($F12,maatregelen!$A$2:$B$1043,2,FALSE)) -> AANVULLEN: Bij aantoonbare noodzaak (met wettelijk belang en alternatievenafweging) productieve vegetaties op rijke gronden een 2e keer maaien, met minimaal zes weken tussen de maaibeurten, waardoor in fasering 100% gemaaid is. De noodzaak hiertoe dient door een ecologisch deskundige goed onderbouwd in het ecologisch werkprotocol te worden opgenomen.
A13: Vogels | B13: 1a | C13: =IF($B13="","",VLOOKUP($B13,werkzaamheden!$A$2:$B$170,2,FALSE)) -> Schonen wateren en maaien oevers - Schieland en Krimpen ad IJssel | D13: 46082 | E13: 46295 | F13: S12 | G13: AANVULLEN: De ecologisch deskundige bepaalt de broedperiode voor de projectspecifieke locatie. Bijvoorbeeld 1 februari t/m 31 oktober.
A14: Vogels | B14: 1a | C14: =IF($B14="","",VLOOKUP($B14,werkzaamheden!$A$2:$B$170,2,FALSE)) -> Schonen wateren en maaien oevers - Schieland en Krimpen ad IJssel | D14: 46054 | E14: 46326 | F14: S13 | G14: =IF($F14="","",VLOOKUP($F14,maatregelen!$A$2:$B$1043,2,FALSE)) -> Indien er binnen de broedperiode van vogels wordt gewerkt, is een locatiebezoek van een ecologisch deskundige nodig. Registreer, markeer en spaar actieve nesten. Spaar minimaal 10 meter vegetatie rond een nest en houdt rekening met voldoende voedsel en dekking voor de jonge vogels.
A15: Bever | B15: 1a | C15: =IF($B15="","",VLOOKUP($B15,werkzaamheden!$A$2:$B$170,2,FALSE)) -> Schonen wateren en maaien oevers - Schieland en Krimpen ad IJssel | D15: 46143 | E15: 46265 | F15: S14 | G15: =IF($F15="","",VLOOKUP($F15,maatregelen!$A$2:$B$1043,2,FALSE)) -> Raadpleeg de GIS -kaart voor de exacte locaties en begrenzingen van essentieel leefgebied en burchten van bever. Zijn er geen burchten of essentieel leefgebied bekend op de specifieke projectlocatie? Dan zijn er geen maatregelen benodigd. Zijn er wel burchten of essentieel leefgebied bekend op de specifieke projectlocatie, schakel dan een beverdeskundige in en pas de maatregelen toe op pagina 43 van de GC. De volgende uitgangspunten gelden: 1.Er worden geen werkzaamheden uitgevoerd in het essentiële leefgebied van bever. Bij aanwezigheid van rust - en voortplantingsplaatsen worden de werkzaamheden uitgevoerd in de periode van september tot en met april. Er mag niet gewerkt worden vanaf de oever waarin zich een hol of burcht bevindt, in de periode net voor en na de zonsondergang dan wel zonsopkomst of bij ijsgang. 2.De beschermingszone en aanpak op basis van behoud van functionaliteit dienen te worden bepaald door de ecologisch deskundige. Buiten de kwetsbare periode (sept – april): indien de werkzaamheden met handkracht worden uitgevoerd zijn de werkzaamheden binnen de beschermingszone toegestaan. Binnen de kwetsbare periode (mei – aug): de werkzaamheden binnen 20 meter van een beverburcht zijn uitsluitend toegestaan wanneer een ecologisch deskundige onderbouwd heeft aangegeven dat hiervan geen verstorende werking uitgaat. 3.Werkzaamheden worden overdag uitgevoerd. 4. Het beheer dient gericht te zijn op behoud van de leefomgeving door gefaseerd te werken in tijd in ruimte met behoud van essentiëlefoerageerlocaties.
A16: Ringslang | B16: 1a | C16: =IF($B16="","",VLOOKUP($B16,werkzaamheden!$A$2:$B$170,2,FALSE)) -> Schonen wateren en maaien oevers - Schieland en Krimpen ad IJssel | D16: 46113 | E16: 46295 | F16: S15 | G16: =IF($F16="","",VLOOKUP($F16,maatregelen!$A$2:$B$1043,2,FALSE)) -> Voer de maaiwerkzaamhedenuit in de winterrustperiode, dit is van oktober tot en met maart. Indien de werkzaamheden in de actieve periode (april tot en met september) worden uitgevoerd, dan alleen maaien bij een temperatuur boven de 15°C , zodat dieren kunnen vluchten. Broeihopen altijd sparen.
A17: Platte schijfhoren | B17: 1a | C17: =IF($B17="","",VLOOKUP($B17,werkzaamheden!$A$2:$B$170,2,FALSE)) -> Schonen wateren en maaien oevers - Schieland en Krimpen ad IJssel | D17: 46023 | E17: 46387 | F17: S16 | G17: =IF($F17="","",VLOOKUP($F17,maatregelen!$A$2:$B$1043,2,FALSE)) -> Voorafgaand aan de schoningswerkzaamheden in bestaand leefgebied dient door een ecologisch deskundige te worden beoordeeld of uitvoering hiervan in betreffende watergang noodzakelijk is.
A18: Platte schijfhoren | B18: 1a | C18: =IF($B18="","",VLOOKUP($B18,werkzaamheden!$A$2:$B$170,2,FALSE)) -> Schonen wateren en maaien oevers - Schieland en Krimpen ad IJssel | D18: 46023 | E18: 46387 | F18: S17 | G18: =IF($F18="","",VLOOKUP($F18,maatregelen!$A$2:$B$1043,2,FALSE)) -> Voorafgaand aan de schoningswerkzaamheden in bestaand leefgebied dient door een ecologisch deskundige te worden beoordeeld of uitvoering hiervan in betreffende watergang noodzakelijk is.
A19: Platte schijfhoren | B19: 1a | C19: =IF($B19="","",VLOOKUP($B19,werkzaamheden!$A$2:$B$170,2,FALSE)) -> Schonen wateren en maaien oevers - Schieland en Krimpen ad IJssel | D19: 46023 | E19: 46387 | F19: s18 | G19: =IF($F19="","",VLOOKUP($F19,maatregelen!$A$2:$B$1043,2,FALSE)) -> In zowel bestaand als geschikt leefgebied geldt dat een locatiebezoek nodig is, uitgevoerd door de ecologisch deskundige met aantoonbare expertise en ervaring met platte schijfhoren.
A20: Platte schijfhoren | B20: 1a | C20: =IF($B20="","",VLOOKUP($B20,werkzaamheden!$A$2:$B$170,2,FALSE)) -> Schonen wateren en maaien oevers - Schieland en Krimpen ad IJssel | D20: 46023 | E20: 46387 | F20: s19 | G20: =IF($F20="","",VLOOKUP($F20,maatregelen!$A$2:$B$1043,2,FALSE)) -> In geschikt leefgebied geldt: voorlopen en indien de soort aanwezig is, dan ook nalopen. In bestaand leefgebied altijd voor- en nalopen. Voorlopen dient plaats te vinden in de periode van juni tot en met september, uiteraard voordat er geschoond is. Tijdens het nalopen worden waterplanten met eieren en individuen teruggeplaatst .
A21: Platte schijfhoren | B21: 1a | C21: =IF($B21="","",VLOOKUP($B21,werkzaamheden!$A$2:$B$170,2,FALSE)) -> Schonen wateren en maaien oevers - Schieland en Krimpen ad IJssel | D21: 46023 | E21: 46387 | F21: s20 | G21: =IF($F21="","",VLOOKUP($F21,maatregelen!$A$2:$B$1043,2,FALSE)) -> Betrek een ecologisch deskundige met aantoonbare expertise en ervaring met platte schijfhoren. Vermijd werkzaamheden op locaties waar eieren of individuen van platte schijfhoren op waterplanten voorkomen.
A22: Platte schijfhoren | B22: 1a | C22: =IF($B22="","",VLOOKUP($B22,werkzaamheden!$A$2:$B$170,2,FALSE)) -> Schonen wateren en maaien oevers - Schieland en Krimpen ad IJssel | D22: 46023 | E22: 46387 | F22: s21 | G22: =IF($F22="","",VLOOKUP($F22,maatregelen!$A$2:$B$1043,2,FALSE)) -> Waardevolle locaties (waterplanten met eieren of individuen )moeten worden ontzien én de werkzaamheden dienen gefaseerd te worden uitgevoerd: per jaar dient minimaal 50% van de watervegetatie en waterboden gespaard te blijven. De waardevolle locaties worden gevonden door middel van een locatiebezoek (voorlopen). Let op: de populatiegrootte neemt toe vanaf juni, hou er dus rekening mee dat in juni weinig tot geen individuen gevonden kunnen worden.
A23: Grote modderkruiper | B23: 1a | C23: =IF($B23="","",VLOOKUP($B23,werkzaamheden!$A$2:$B$170,2,FALSE)) -> Schonen wateren en maaien oevers - Schieland en Krimpen ad IJssel | D23: 46023 | E23: 46387 | F23: S22 | G23: =IF($F23="","",VLOOKUP($F23,maatregelen!$A$2:$B$1043,2,FALSE)) -> Locatiebezoek (nalopen) is nodig. Dit vindt direct na de werkzaamheden plaats en wordt door een ecologisch deskundige gecoördineerd of uitgevoerd. Het schoonsel wordt op de kant verspreid. Meegekomen dieren worden direct teruggeplaatst in het water. Bij voorkeur worden de werkzaamheden uitgevoerd in de maanden september en oktober.
A24: Grote modderkruiper | B24: 1a | C24: =IF($B24="","",VLOOKUP($B24,werkzaamheden!$A$2:$B$170,2,FALSE)) -> Schonen wateren en maaien oevers - Schieland en Krimpen ad IJssel | D24: 46023 | E24: 46387 | F24: S23 | G24: =IF($F24="","",VLOOKUP($F24,maatregelen!$A$2:$B$1043,2,FALSE)) -> Er worden geen werkzaamheden uitgevoerd bij watertemperaturen onder de 5 graden Celsius en boven de 25 graden Celsius. Het zuurstofgehalte in het water moet boven de 4 mg/l blijven. Bij waarneming van slome vissen of vissen die happen aan het oppervlak, moeten de werkzaamheden direct worden stilgelegd.
A25: Groene glazenmaker | B25: 1a | C25: =IF($B25="","",VLOOKUP($B25,werkzaamheden!$A$2:$B$170,2,FALSE)) -> Schonen wateren en maaien oevers - Schieland en Krimpen ad IJssel | D25: 46023 | E25: 46387 | F25: S24 | G25: =IF($F25="","",VLOOKUP($F25,maatregelen!$A$2:$B$1043,2,FALSE)) -> AANVULLEN: Indien de werkzaamheden plaatsvinden in leefgebied, dan werkt de ecologisch deskundige de relevante elementen uit in het UP.
... A50: Groot leermos | B50: 2d | C50: =IF($B50="","",VLOOKUP($B50,werkzaamheden!$A$2:$B$170,2,FALSE)) -> Maaien eigen terreinen en rond kunstwerken | D50: 46023 | E50: 46387 | F50: S42 | G50: =IF($F50="","",VLOOKUP($F50,maatregelen!$A$2:$B$1043,2,FALSE)) -> Voorterrein AWZI Kralingse Veer. Voorkom bodemverdichting door niet met zware machines te werken. Ruim het maaisel af, maximaal 3 dagen na het maaien.
A51: Vogels | B51: 1b | C51: Schonen van wateren - Krimpenerwaard | D51: 46082 | E51: 46295 | F51: S12 | G51: AANVULLEN: De ecologisch deskundige bepaalt de broedperiode voor de projectspecifieke locatie. Bijvoorbeeld 1 februari t/m 31 oktober.
A52: Vogels | B52: 1b | C52: =IF($B52="","",VLOOKUP($B52,werkzaamheden!$A$2:$B$170,2,FALSE)) -> Schonen van wateren - Krimpenerwaard | D52: 46054 | E52: 46326 | F52: S13 | G52: =IF($F52="","",VLOOKUP($F52,maatregelen!$A$2:$B$1043,2,FALSE)) -> Indien er binnen de broedperiode van vogels wordt gewerkt, is een locatiebezoek van een ecologisch deskundige nodig. Registreer, markeer en spaar actieve nesten. Spaar minimaal 10 meter vegetatie rond een nest en houdt rekening met voldoende voedsel en dekking voor de jonge vogels.
A53: Zwarte stern | B53: 1b | C53: =IF($B53="","",VLOOKUP($B53,werkzaamheden!$A$2:$B$170,2,FALSE)) -> Schonen van wateren - Krimpenerwaard | D53: 46023 | E53: 46387 | F53: S43 | G53: =IF($F53="","",VLOOKUP($F53,maatregelen!$A$2:$B$1043,2,FALSE)) -> Werkbare periode: juli tot en met april. Bij broedlocaties van zwarte stern dient de watergang voor 50% bedekt te blijven met krabbenscheer.
A54: Zwarte stern | B54: 3 | C54: =IF($B54="","",VLOOKUP($B54,werkzaamheden!$A$2:$B$170,2,FALSE)) -> Baggeren van wateren (onderhoud) | D54: 46023 | E54: 46387 | F54: S44 | G54: Werkbare periode: juli tot en met april. Bij broedlocaties van zwarte stern dient de watergang voor 50% bedekt te blijven met krabbenscheer.
A55: Bever | B55: 1b | C55: =IF($B55="","",VLOOKUP($B55,werkzaamheden!$A$2:$B$170,2,FALSE)) -> Schonen van wateren - Krimpenerwaard | D55: 46143 | E55: 46265 | F55: S14 | G55: =IF($F55="","",VLOOKUP($F55,maatregelen!$A$2:$B$1043,2,FALSE)) -> Raadpleeg de GIS -kaart voor de exacte locaties en begrenzingen van essentieel leefgebied en burchten van bever. Zijn er geen burchten of essentieel leefgebied bekend op de specifieke projectlocatie? Dan zijn er geen maatregelen benodigd. Zijn er wel burchten of essentieel leefgebied bekend op de specifieke projectlocatie, schakel dan een beverdeskundige in en pas de maatregelen toe op pagina 43 van de GC. De volgende uitgangspunten gelden: 1.Er worden geen werkzaamheden uitgevoerd in het essentiële leefgebied van bever. Bij aanwezigheid van rust - en voortplantingsplaatsen worden de werkzaamheden uitgevoerd in de periode van september tot en met april. Er mag niet gewerkt worden vanaf de oever waarin zich een hol of burcht bevindt, in de periode net voor en na de zonsondergang dan wel zonsopkomst of bij ijsgang. 2.De beschermingszone en aanpak op basis van behoud van functionaliteit dienen te worden bepaald door de ecologisch deskundige. Buiten de kwetsbare periode (sept – april): indien de werkzaamheden met handkracht worden uitgevoerd zijn de werkzaamheden binnen de beschermingszone toegestaan. Binnen de kwetsbare periode (mei – aug): de werkzaamheden binnen 20 meter van een beverburcht zijn uitsluitend toegestaan wanneer een ecologisch deskundige onderbouwd heeft aangegeven dat hiervan geen verstorende werking uitgaat. 3.Werkzaamheden worden overdag uitgevoerd. 4. Het beheer dient gericht te zijn op behoud van de leefomgeving door gefaseerd te werken in tijd in ruimte met behoud van essentiëlefoerageerlocaties.
A56: Grote modderkruiper | B56: 1b | C56: =IF($B56="","",VLOOKUP($B56,werkzaamheden!$A$2:$B$170,2,FALSE)) -> Schonen van wateren - Krimpenerwaard | D56: 46023 | E56: 46388 | F56: S22 | G56: =IF($F56="","",VLOOKUP($F56,maatregelen!$A$2:$B$1043,2,FALSE)) -> Locatiebezoek (nalopen) is nodig. Dit vindt direct na de werkzaamheden plaats en wordt door een ecologisch deskundige gecoördineerd of uitgevoerd. Het schoonsel wordt op de kant verspreid. Meegekomen dieren worden direct teruggeplaatst in het water. Bij voorkeur worden de werkzaamheden uitgevoerd in de maanden september en oktober.
A57: Grote modderkruiper | B57: 1b | C57: =IF($B57="","",VLOOKUP($B57,werkzaamheden!$A$2:$B$170,2,FALSE)) -> Schonen van wateren - Krimpenerwaard | D57: 46023 | E57: 46388 | F57: S23 | G57: =IF($F57="","",VLOOKUP($F57,maatregelen!$A$2:$B$1043,2,FALSE)) -> Er worden geen werkzaamheden uitgevoerd bij watertemperaturen onder de 5 graden Celsius en boven de 25 graden Celsius. Het zuurstofgehalte in het water moet boven de 4 mg/l blijven. Bij waarneming van slome vissen of vissen die happen aan het oppervlak, moeten de werkzaamheden direct worden stilgelegd.
A58: Platte schijfhoren | B58: 1b | C58: =IF($B58="","",VLOOKUP($B58,werkzaamheden!$A$2:$B$170,2,FALSE)) -> Schonen van wateren - Krimpenerwaard | D58: 46023 | E58: 46387 | F58: S16 | G58: =IF($F58="","",VLOOKUP($F58,maatregelen!$A$2:$B$1043,2,FALSE)) -> Voorafgaand aan de schoningswerkzaamheden in bestaand leefgebied dient door een ecologisch deskundige te worden beoordeeld of uitvoering hiervan in betreffende watergang noodzakelijk is.
A59: Platte schijfhoren | B59: 1b | C59: =IF($B59="","",VLOOKUP($B59,werkzaamheden!$A$2:$B$170,2,FALSE)) -> Schonen van wateren - Krimpenerwaard | D59: 46023 | E59: 46387 | F59: S17 | G59: =IF($F59="","",VLOOKUP($F59,maatregelen!$A$2:$B$1043,2,FALSE)) -> Voorafgaand aan de schoningswerkzaamheden in bestaand leefgebied dient door een ecologisch deskundige te worden beoordeeld of uitvoering hiervan in betreffende watergang noodzakelijk is.
A60: Platte schijfhoren | B60: 1b | C60: =IF($B60="","",VLOOKUP($B60,werkzaamheden!$A$2:$B$170,2,FALSE)) -> Schonen van wateren - Krimpenerwaard | D60: 46023 | E60: 46387 | F60: s18 | G60: =IF($F60="","",VLOOKUP($F60,maatregelen!$A$2:$B$1043,2,FALSE)) -> In zowel bestaand als geschikt leefgebied geldt dat een locatiebezoek nodig is, uitgevoerd door de ecologisch deskundige met aantoonbare expertise en ervaring met platte schijfhoren.
A61: Platte schijfhoren | B61: 1b | C61: =IF($B61="","",VLOOKUP($B61,werkzaamheden!$A$2:$B$170,2,FALSE)) -> Schonen van wateren - Krimpenerwaard | D61: 46023 | E61: 46387 | F61: s19 | G61: =IF($F61="","",VLOOKUP($F61,maatregelen!$A$2:$B$1043,2,FALSE)) -> In geschikt leefgebied geldt: voorlopen en indien de soort aanwezig is, dan ook nalopen. In bestaand leefgebied altijd voor- en nalopen. Voorlopen dient plaats te vinden in de periode van juni tot en met september, uiteraard voordat er geschoond is. Tijdens het nalopen worden waterplanten met eieren en individuen teruggeplaatst .
A62: Platte schijfhoren | B62: 1b | C62: =IF($B62="","",VLOOKUP($B62,werkzaamheden!$A$2:$B$170,2,FALSE)) -> Schonen van wateren - Krimpenerwaard | D62: 46023 | E62: 46387 | F62: s20 | G62: =IF($F62="","",VLOOKUP($F62,maatregelen!$A$2:$B$1043,2,FALSE)) -> Betrek een ecologisch deskundige met aantoonbare expertise en ervaring met platte schijfhoren. Vermijd werkzaamheden op locaties waar eieren of individuen van platte schijfhoren op waterplanten voorkomen.
A63: Platte schijfhoren | B63: 1b | C63: =IF($B63="","",VLOOKUP($B63,werkzaamheden!$A$2:$B$170,2,FALSE)) -> Schonen van wateren - Krimpenerwaard | D63: 46023 | E63: 46387 | F63: s21 | G63: =IF($F63="","",VLOOKUP($F63,maatregelen!$A$2:$B$1043,2,FALSE)) -> Waardevolle locaties (waterplanten met eieren of individuen )moeten worden ontzien én de werkzaamheden dienen gefaseerd te worden uitgevoerd: per jaar dient minimaal 50% van de watervegetatie en waterboden gespaard te blijven. De waardevolle locaties worden gevonden door middel van een locatiebezoek (voorlopen). Let op: de populatiegrootte neemt toe vanaf juni, hou er dus rekening mee dat in juni weinig tot geen individuen gevonden kunnen worden.
A64: Groene glazenmaker | B64: 1b | C64: =IF($B64="","",VLOOKUP($B64,werkzaamheden!$A$2:$B$170,2,FALSE)) -> Schonen van wateren - Krimpenerwaard | D64: 46174 | E64: 46295 | F64: S25 | G64: =IF($F64="","",VLOOKUP($F64,maatregelen!$A$2:$B$1043,2,FALSE)) -> De relevante elementen moeten worden behouden door gefaseerd te werken. Behoud structuurelementen en een verscheidenheid aan verlandingsstadia, zoals waterplanten, riet en ruigte en een flauw oevertalud. Behoud minimaal 25% van de oevervegetatie. Tenminste 25% van de relevante structuurelementen in het essentieel leefgebied van de lokale populatie mag niet worden aangetast, maar liever 50%. Sloten mogen niet jaarlijks geschoond worden. Spaar elke onderhoudsbeurt minimaal 50% van de onderwatervegetatie en de waterbodem, iedere keer een andere 50%.
...

Sheet Vraagstukken
A1: Let op: bij EWP's 1b+1c+2a+2b+3 is het enkel mogelijk om volgens de habitatbenadering te werken! Er zijn daarom geen maatregelen opgenomen als niet volgens de habitatbenadering wordt gewerkt. Dit moet dan echter wel de enige keuzemogelijkheid zijn bij de invoer.
A2: Bij 2d wordt niet volgens de HB gewerkt
A4: Uitleg voor Johan, kolom habitatbenadering (kolom E, tab maatregelen):
A5: JA=De habitatbenadering wordt toegepast. Dit moet de gebruiker zelf invullen. Maar bij de EWP's 1b, 1c, 2a, 2b, 2c en 3 (zie tab: werkzaamheden) is dit de standaardstrategie die wordt toegepast en zou er eigenlijk geen andere keuze moeten zijn. Wil je toch afwijken, dan vraagt dit om maatwerk en kan deze UP-module niet toegpast worden. Misschien ooit in een later stadium wel, maar we zijn er nu niet op ingericht.
A6: NEE= een maatregel die nodig is als de habitatbenadering wordt niet toegepast, dit levert vaak meerdere specifieke maatregelen op, omdat er minder habitat gespaard kan blijven (uitgangsount habitatbenadering).
A7: LEEG=de maatregel is onafhankelijk van of de habitatbenadering wel of niet toegepast wordt. Altijd opnemen.
A8: Disclaimer - als er nieuwe soorten of leefgebieden worden gevonden dan zijn deze nog niet opgenomen.
A9: Tabblad gebied soorten is nog niet compleet
